Failure # 1 (occurred at 2023-06-20_12-08-47)
Traceback (most recent call last):
  File "/home/viswesh-n/anaconda3/envs/marl/lib/python3.9/site-packages/ray/tune/execution/ray_trial_executor.py", line 989, in get_next_executor_event
    future_result = ray.get(ready_future)
  File "/home/viswesh-n/anaconda3/envs/marl/lib/python3.9/site-packages/ray/_private/client_mode_hook.py", line 105, in wrapper
    return func(*args, **kwargs)
  File "/home/viswesh-n/anaconda3/envs/marl/lib/python3.9/site-packages/ray/_private/worker.py", line 2277, in get
    raise value
ray.exceptions.RayActorError: The actor died because of an error raised in its creation task, [36mray::PPO.__init__()[39m (pid=61303, ip=100.67.195.83, repr=PPO)
  File "/home/viswesh-n/anaconda3/envs/marl/lib/python3.9/site-packages/ray/rllib/algorithms/algorithm.py", line 308, in __init__
    super().__init__(config=config, logger_creator=logger_creator, **kwargs)
  File "/home/viswesh-n/anaconda3/envs/marl/lib/python3.9/site-packages/ray/tune/trainable/trainable.py", line 157, in __init__
    self.setup(copy.deepcopy(self.config))
  File "/home/viswesh-n/anaconda3/envs/marl/lib/python3.9/site-packages/ray/rllib/algorithms/algorithm.py", line 477, in setup
    assert (
AssertionError

